2024-08-02 14:04:32 [INFO] Question: the heighest value
2024-08-02 14:04:32 [INFO] Running PandasAI with local LLM...
2024-08-02 14:04:32 [INFO] Prompt ID: 026e4bd8-399c-46a5-8145-d0e9b1d49da0
2024-08-02 14:04:32 [INFO] Executing Pipeline: GenerateChatPipeline
2024-08-02 14:04:32 [INFO] Executing Step 0: ValidatePipelineInput
2024-08-02 14:04:32 [INFO] Executing Step 1: CacheLookup
2024-08-02 14:04:32 [INFO] Executing Step 2: PromptGeneration
2024-08-02 14:04:32 [INFO] Using prompt: <dataframe>
dfs[0]:4999x10
1,"Eldon Base for stackable storage shelf, platinum",Muhammed MacIntyre,3,-213.25,38.94,35,Nunavut,Storage & Organization,0.8
4734,Eureka The Boss® Cordless Rechargeable Stick Vac,Jason Gross,47682,-82.16,46.89,2.56,Nova Scotia,Labels,
4157,GBC DocuBind P100 Manual Binding Machine,Matt Hagelstein,22663,753.61,232.58,59.81,Newfoundland,Office Furnishings,0.73
2643,Hayes Optima 56K V.90 Internal Voice Modem,Mike Gockenbach,36135,-281.22,13.73,3.99,Nunavut,Binders and Binder Accessories,0.54
</dataframe>




Update this initial code:
```python
# TODO: import the required dependencies
import pandas as pd

# Write code here

# Declare result var: 
type (possible values "string", "number", "dataframe", "plot"). Examples: { "type": "string", "value": f"The highest salary is {highest_salary}." } or { "type": "number", "value": 125 } or { "type": "dataframe", "value": pd.DataFrame({...}) } or { "type": "plot", "value": "temp_chart.png" }

```



### QUERY
 the heighest value

Variable `dfs: list[pd.DataFrame]` is already declared.

At the end, declare "result" variable as a dictionary of type and value.

If you are asked to plot a chart, use "matplotlib" for charts, save as png.


Generate python code and return full updated code:
2024-08-02 14:04:32 [INFO] Executing Step 3: CodeGenerator
2024-08-02 14:06:15 [INFO] HTTP Request: POST http://localhost:11434/v1/chat/completions "HTTP/1.1 200 OK"
2024-08-02 14:06:15 [ERROR] Pipeline failed on step 3: No code found in the response
2024-08-02 14:07:45 [INFO] Question: heighest value
2024-08-02 14:07:45 [INFO] Running PandasAI with local LLM...
2024-08-02 14:07:45 [INFO] Prompt ID: 9416e67d-89b9-43aa-a42a-f9c43f51e1a8
2024-08-02 14:07:45 [INFO] Executing Pipeline: GenerateChatPipeline
2024-08-02 14:07:45 [INFO] Executing Step 0: ValidatePipelineInput
2024-08-02 14:07:45 [INFO] Executing Step 1: CacheLookup
2024-08-02 14:07:45 [INFO] Executing Step 2: PromptGeneration
2024-08-02 14:07:45 [INFO] Using prompt: <dataframe>
dfs[0]:4999x10
1,"Eldon Base for stackable storage shelf, platinum",Muhammed MacIntyre,3,-213.25,38.94,35,Nunavut,Storage & Organization,0.8
1098,Computer Printout Index Tabs,Tracy Collins,47520,-156.41,20.95,3.37,Ontario,Labels,0.49
674,688,Rose O'Brian,43236,1215.28,500.97,0.8,Nova Scotia,Chairs & Chairmats,
4951,Xerox 1989,Liz Price,293,545.49,41.94,14.36,New Brunswick,Office Furnishings,0.7
</dataframe>




Update this initial code:
```python
# TODO: import the required dependencies
import pandas as pd

# Write code here

# Declare result var: 
type (possible values "string", "number", "dataframe", "plot"). Examples: { "type": "string", "value": f"The highest salary is {highest_salary}." } or { "type": "number", "value": 125 } or { "type": "dataframe", "value": pd.DataFrame({...}) } or { "type": "plot", "value": "temp_chart.png" }

```



### QUERY
 heighest value

Variable `dfs: list[pd.DataFrame]` is already declared.

At the end, declare "result" variable as a dictionary of type and value.

If you are asked to plot a chart, use "matplotlib" for charts, save as png.


Generate python code and return full updated code:
2024-08-02 14:07:45 [INFO] Executing Step 3: CodeGenerator
2024-08-02 14:09:36 [INFO] HTTP Request: POST http://localhost:11434/v1/chat/completions "HTTP/1.1 200 OK"
2024-08-02 14:09:36 [INFO] Prompt used:
            <dataframe>
dfs[0]:4999x10
1,"Eldon Base for stackable storage shelf, platinum",Muhammed MacIntyre,3,-213.25,38.94,35,Nunavut,Storage & Organization,0.8
1098,Computer Printout Index Tabs,Tracy Collins,47520,-156.41,20.95,3.37,Ontario,Labels,0.49
674,688,Rose O'Brian,43236,1215.28,500.97,0.8,Nova Scotia,Chairs & Chairmats,
4951,Xerox 1989,Liz Price,293,545.49,41.94,14.36,New Brunswick,Office Furnishings,0.7
</dataframe>




Update this initial code:
```python
# TODO: import the required dependencies
import pandas as pd

# Write code here

# Declare result var: 
type (possible values "string", "number", "dataframe", "plot"). Examples: { "type": "string", "value": f"The highest salary is {highest_salary}." } or { "type": "number", "value": 125 } or { "type": "dataframe", "value": pd.DataFrame({...}) } or { "type": "plot", "value": "temp_chart.png" }

```



### QUERY
 heighest value

Variable `dfs: list[pd.DataFrame]` is already declared.

At the end, declare "result" variable as a dictionary of type and value.

If you are asked to plot a chart, use "matplotlib" for charts, save as png.


Generate python code and return full updated code:
            
2024-08-02 14:09:36 [INFO] Code generated:
            ```
            # TODO: import the required dependencies
import pandas as pd
from matplotlib import pyplot as plt

def generate_chart(highest_salary):
    
    # Declare result var:
    possible_values = {"type": "string", "value": f"The highest salary is {highest_salary}."}
    
    return possible_values

if __name__ == '__main__':
    
    # Sample data
    dfs = pd.read_csv("data.csv")
    
    # Generate chart (type: "chart") and save as png ("output.png")
    try:
        result = generate_chart(highest_salary)                # Replace with your desired type and value
        plt.imshow(result['value'])
        plt.xticks([])
        plt.yticks([])
    
        plt.savefig("output.png")                             # Save as png. Example: `! python main.py input.csv output.png`
    except Exception as e:
        print(f"Error: {e}")
            ```
            
2024-08-02 14:09:36 [INFO] Executing Step 4: CachePopulation
2024-08-02 14:09:36 [INFO] Executing Step 5: CodeCleaning
2024-08-02 14:09:36 [INFO] Saving charts to C:\Users\Anesti\Desktop\New folder (4)\exports\charts\temp_chart.png
2024-08-02 14:09:36 [INFO] 
Code running:
```
def generate_chart(highest_salary):
    possible_values = {'type': 'string', 'value': f'The highest salary is {highest_salary}.'}
    return possible_values


if __name__ == '__main__':
    dfs = pd.read_csv('data.csv')
    try:
        result = generate_chart(highest_salary)
        plt.imshow(result['value'])
        plt.xticks([])
        plt.yticks([])
        plt.savefig('C:/Users/Anesti/Desktop/New folder (4)/exports/charts/temp_chart.png')
    except Exception as e:
        print(f'Error: {e}')
        ```
2024-08-02 14:09:36 [INFO] Executing Step 6: CodeExecution
2024-08-02 14:09:36 [ERROR] Failed with error: Traceback (most recent call last):
  File "C:\users\anesti\appdata\local\programs\python\python39\lib\site-packages\pandasai\pipelines\chat\code_execution.py", line 85, in execute
    result = self.execute_code(code_to_run, code_context)
  File "C:\users\anesti\appdata\local\programs\python\python39\lib\site-packages\pandasai\pipelines\chat\code_execution.py", line 171, in execute_code
    exec(code, environment)
  File "<string>", line 7, in <module>
  File "C:\users\anesti\appdata\local\programs\python\python39\lib\site-packages\pandas\util\_decorators.py", line 211, in wrapper
    return func(*args, **kwargs)
  File "C:\users\anesti\appdata\local\programs\python\python39\lib\site-packages\pandas\util\_decorators.py", line 331, in wrapper
    return func(*args, **kwargs)
  File "C:\users\anesti\appdata\local\programs\python\python39\lib\site-packages\pandas\io\parsers\readers.py", line 950, in read_csv
    return _read(filepath_or_buffer, kwds)
  File "C:\users\anesti\appdata\local\programs\python\python39\lib\site-packages\pandas\io\parsers\readers.py", line 605, in _read
    parser = TextFileReader(filepath_or_buffer, **kwds)
  File "C:\users\anesti\appdata\local\programs\python\python39\lib\site-packages\pandas\io\parsers\readers.py", line 1442, in __init__
    self._engine = self._make_engine(f, self.engine)
  File "C:\users\anesti\appdata\local\programs\python\python39\lib\site-packages\pandas\io\parsers\readers.py", line 1735, in _make_engine
    self.handles = get_handle(
  File "C:\users\anesti\appdata\local\programs\python\python39\lib\site-packages\pandas\io\common.py", line 856, in get_handle
    handle = open(
FileNotFoundError: [Errno 2] No such file or directory: 'data.csv'

2024-08-02 14:09:36 [WARNING] Failed to execute code retrying with a correction framework [retry number: 1]
2024-08-02 14:09:36 [INFO] Executing Pipeline: ErrorCorrectionPipeline
2024-08-02 14:09:36 [INFO] Executing Step 0: ErrorPromptGeneration
2024-08-02 14:09:36 [INFO] Using prompt: <dataframe>
dfs[0]:4999x10
1,"Eldon Base for stackable storage shelf, platinum",Muhammed MacIntyre,3,-213.25,38.94,35,Nunavut,Storage & Organization,0.8
1098,Computer Printout Index Tabs,Tracy Collins,47520,-156.41,20.95,3.37,Ontario,Labels,0.49
674,688,Rose O'Brian,43236,1215.28,500.97,0.8,Nova Scotia,Chairs & Chairmats,
4951,Xerox 1989,Liz Price,293,545.49,41.94,14.36,New Brunswick,Office Furnishings,0.7
</dataframe>


The user asked the following question:
### QUERY
 heighest value

You generated this python code:
def generate_chart(highest_salary):
    possible_values = {'type': 'string', 'value': f'The highest salary is {highest_salary}.'}
    return possible_values


if __name__ == '__main__':
    dfs = pd.read_csv('data.csv')
    try:
        result = generate_chart(highest_salary)
        plt.imshow(result['value'])
        plt.xticks([])
        plt.yticks([])
        plt.savefig('C:/Users/Anesti/Desktop/New folder (4)/exports/charts/temp_chart.png')
    except Exception as e:
        print(f'Error: {e}')

It fails with the following error:
Traceback (most recent call last):
  File "C:\users\anesti\appdata\local\programs\python\python39\lib\site-packages\pandasai\pipelines\chat\code_execution.py", line 85, in execute
    result = self.execute_code(code_to_run, code_context)
  File "C:\users\anesti\appdata\local\programs\python\python39\lib\site-packages\pandasai\pipelines\chat\code_execution.py", line 171, in execute_code
    exec(code, environment)
  File "<string>", line 7, in <module>
  File "C:\users\anesti\appdata\local\programs\python\python39\lib\site-packages\pandas\util\_decorators.py", line 211, in wrapper
    return func(*args, **kwargs)
  File "C:\users\anesti\appdata\local\programs\python\python39\lib\site-packages\pandas\util\_decorators.py", line 331, in wrapper
    return func(*args, **kwargs)
  File "C:\users\anesti\appdata\local\programs\python\python39\lib\site-packages\pandas\io\parsers\readers.py", line 950, in read_csv
    return _read(filepath_or_buffer, kwds)
  File "C:\users\anesti\appdata\local\programs\python\python39\lib\site-packages\pandas\io\parsers\readers.py", line 605, in _read
    parser = TextFileReader(filepath_or_buffer, **kwds)
  File "C:\users\anesti\appdata\local\programs\python\python39\lib\site-packages\pandas\io\parsers\readers.py", line 1442, in __init__
    self._engine = self._make_engine(f, self.engine)
  File "C:\users\anesti\appdata\local\programs\python\python39\lib\site-packages\pandas\io\parsers\readers.py", line 1735, in _make_engine
    self.handles = get_handle(
  File "C:\users\anesti\appdata\local\programs\python\python39\lib\site-packages\pandas\io\common.py", line 856, in get_handle
    handle = open(
FileNotFoundError: [Errno 2] No such file or directory: 'data.csv'


Fix the python code above and return the new python code:
2024-08-02 14:09:36 [INFO] Executing Step 1: CodeGenerator
2024-08-02 14:11:11 [INFO] HTTP Request: POST http://localhost:11434/v1/chat/completions "HTTP/1.1 200 OK"
2024-08-02 14:11:11 [ERROR] Pipeline failed on step 1: No code found in the response
2024-08-02 14:11:11 [ERROR] Pipeline failed on step 6: No code found in the response
2024-08-02 14:23:12 [INFO] Question: heighest value
2024-08-02 14:23:12 [INFO] Running PandasAI with local LLM...
2024-08-02 14:23:12 [INFO] Prompt ID: c5fb9c26-0011-4f14-86a9-0aa3144058b4
2024-08-02 14:23:12 [INFO] Executing Pipeline: GenerateChatPipeline
2024-08-02 14:23:12 [INFO] Executing Step 0: ValidatePipelineInput
2024-08-02 14:23:12 [INFO] Executing Step 1: CacheLookup
2024-08-02 14:23:12 [INFO] Using cached response
2024-08-02 14:23:12 [INFO] Executing Step 2: PromptGeneration
2024-08-02 14:23:12 [INFO] Executing Step 2: Skipping...
2024-08-02 14:23:12 [INFO] Executing Step 3: CodeGenerator
2024-08-02 14:23:12 [INFO] Executing Step 3: Skipping...
2024-08-02 14:23:12 [INFO] Executing Step 4: CachePopulation
2024-08-02 14:23:12 [INFO] Executing Step 4: Skipping...
2024-08-02 14:23:12 [INFO] Executing Step 5: CodeCleaning
2024-08-02 14:23:12 [INFO] Saving charts to C:\Users\Anesti\Desktop\New folder (4)\exports\charts\temp_chart.png
2024-08-02 14:23:12 [INFO] 
Code running:
```
def generate_chart(highest_salary):
    possible_values = {'type': 'string', 'value': f'The highest salary is {highest_salary}.'}
    return possible_values


if __name__ == '__main__':
    dfs = pd.read_csv('data.csv')
    try:
        result = generate_chart(highest_salary)
        plt.imshow(result['value'])
        plt.xticks([])
        plt.yticks([])
        plt.savefig('C:/Users/Anesti/Desktop/New folder (4)/exports/charts/temp_chart.png')
    except Exception as e:
        print(f'Error: {e}')
        ```
2024-08-02 14:23:12 [INFO] Executing Step 6: CodeExecution
2024-08-02 14:23:12 [ERROR] Failed with error: Traceback (most recent call last):
  File "C:\users\anesti\appdata\local\programs\python\python39\lib\site-packages\pandasai\pipelines\chat\code_execution.py", line 85, in execute
    result = self.execute_code(code_to_run, code_context)
  File "C:\users\anesti\appdata\local\programs\python\python39\lib\site-packages\pandasai\pipelines\chat\code_execution.py", line 171, in execute_code
    exec(code, environment)
  File "<string>", line 7, in <module>
  File "C:\users\anesti\appdata\local\programs\python\python39\lib\site-packages\pandas\util\_decorators.py", line 211, in wrapper
    return func(*args, **kwargs)
  File "C:\users\anesti\appdata\local\programs\python\python39\lib\site-packages\pandas\util\_decorators.py", line 331, in wrapper
    return func(*args, **kwargs)
  File "C:\users\anesti\appdata\local\programs\python\python39\lib\site-packages\pandas\io\parsers\readers.py", line 950, in read_csv
    return _read(filepath_or_buffer, kwds)
  File "C:\users\anesti\appdata\local\programs\python\python39\lib\site-packages\pandas\io\parsers\readers.py", line 605, in _read
    parser = TextFileReader(filepath_or_buffer, **kwds)
  File "C:\users\anesti\appdata\local\programs\python\python39\lib\site-packages\pandas\io\parsers\readers.py", line 1442, in __init__
    self._engine = self._make_engine(f, self.engine)
  File "C:\users\anesti\appdata\local\programs\python\python39\lib\site-packages\pandas\io\parsers\readers.py", line 1735, in _make_engine
    self.handles = get_handle(
  File "C:\users\anesti\appdata\local\programs\python\python39\lib\site-packages\pandas\io\common.py", line 856, in get_handle
    handle = open(
FileNotFoundError: [Errno 2] No such file or directory: 'data.csv'

2024-08-02 14:23:12 [WARNING] Failed to execute code retrying with a correction framework [retry number: 1]
2024-08-02 14:23:12 [INFO] Executing Pipeline: ErrorCorrectionPipeline
2024-08-02 14:23:12 [INFO] Executing Step 0: ErrorPromptGeneration
2024-08-02 14:23:12 [INFO] Using prompt: <dataframe>
dfs[0]:4999x10
1,"Eldon Base for stackable storage shelf, platinum",Muhammed MacIntyre,3,-213.25,38.94,35,Nunavut,Storage & Organization,0.8
4356,VTech VT20-2481 2.4GHz Two-Line Phone System w/Answering Machine,Natalie Fritzler,54020,-22.63,291.73,10.16,Northwest Territories,Storage & Organization,
1422,Xerox 1898,Aaron Bergman,4007,-1561.72,9.27,7.1,Manitoba,Paper,0.64
4163,Xerox 1948,Christina DeMoss,20451,-99.08,7.45,7.27,Quebec,Bookcases,0.44
</dataframe>


The user asked the following question:
### QUERY
 heighest value

You generated this python code:
def generate_chart(highest_salary):
    possible_values = {'type': 'string', 'value': f'The highest salary is {highest_salary}.'}
    return possible_values


if __name__ == '__main__':
    dfs = pd.read_csv('data.csv')
    try:
        result = generate_chart(highest_salary)
        plt.imshow(result['value'])
        plt.xticks([])
        plt.yticks([])
        plt.savefig('C:/Users/Anesti/Desktop/New folder (4)/exports/charts/temp_chart.png')
    except Exception as e:
        print(f'Error: {e}')

It fails with the following error:
Traceback (most recent call last):
  File "C:\users\anesti\appdata\local\programs\python\python39\lib\site-packages\pandasai\pipelines\chat\code_execution.py", line 85, in execute
    result = self.execute_code(code_to_run, code_context)
  File "C:\users\anesti\appdata\local\programs\python\python39\lib\site-packages\pandasai\pipelines\chat\code_execution.py", line 171, in execute_code
    exec(code, environment)
  File "<string>", line 7, in <module>
  File "C:\users\anesti\appdata\local\programs\python\python39\lib\site-packages\pandas\util\_decorators.py", line 211, in wrapper
    return func(*args, **kwargs)
  File "C:\users\anesti\appdata\local\programs\python\python39\lib\site-packages\pandas\util\_decorators.py", line 331, in wrapper
    return func(*args, **kwargs)
  File "C:\users\anesti\appdata\local\programs\python\python39\lib\site-packages\pandas\io\parsers\readers.py", line 950, in read_csv
    return _read(filepath_or_buffer, kwds)
  File "C:\users\anesti\appdata\local\programs\python\python39\lib\site-packages\pandas\io\parsers\readers.py", line 605, in _read
    parser = TextFileReader(filepath_or_buffer, **kwds)
  File "C:\users\anesti\appdata\local\programs\python\python39\lib\site-packages\pandas\io\parsers\readers.py", line 1442, in __init__
    self._engine = self._make_engine(f, self.engine)
  File "C:\users\anesti\appdata\local\programs\python\python39\lib\site-packages\pandas\io\parsers\readers.py", line 1735, in _make_engine
    self.handles = get_handle(
  File "C:\users\anesti\appdata\local\programs\python\python39\lib\site-packages\pandas\io\common.py", line 856, in get_handle
    handle = open(
FileNotFoundError: [Errno 2] No such file or directory: 'data.csv'


Fix the python code above and return the new python code:
2024-08-02 14:23:12 [INFO] Executing Step 1: CodeGenerator
2024-08-02 14:25:20 [INFO] HTTP Request: POST http://localhost:11434/v1/chat/completions "HTTP/1.1 200 OK"
2024-08-02 14:25:20 [ERROR] Pipeline failed on step 1: No code found in the response
2024-08-02 14:25:20 [ERROR] Pipeline failed on step 6: No code found in the response
2024-08-02 14:49:22 [INFO] Question: heighest value
2024-08-02 14:49:22 [INFO] Running PandasAI with openai LLM...
2024-08-02 14:49:22 [INFO] Prompt ID: 986187d9-ba30-4807-a02b-94db609c6158
2024-08-02 14:49:22 [INFO] Executing Pipeline: GenerateChatPipeline
2024-08-02 14:49:22 [INFO] Executing Step 0: ValidatePipelineInput
2024-08-02 14:49:22 [INFO] Executing Step 1: CacheLookup
2024-08-02 14:49:22 [INFO] Using cached response
2024-08-02 14:49:22 [INFO] Executing Step 2: PromptGeneration
2024-08-02 14:49:22 [INFO] Executing Step 2: Skipping...
2024-08-02 14:49:22 [INFO] Executing Step 3: CodeGenerator
2024-08-02 14:49:22 [INFO] Executing Step 3: Skipping...
2024-08-02 14:49:22 [INFO] Executing Step 4: CachePopulation
2024-08-02 14:49:22 [INFO] Executing Step 4: Skipping...
2024-08-02 14:49:22 [INFO] Executing Step 5: CodeCleaning
2024-08-02 14:49:22 [INFO] Saving charts to C:\Users\Anesti\Desktop\New folder (4)\exports\charts\temp_chart.png
2024-08-02 14:49:22 [INFO] 
Code running:
```
def generate_chart(highest_salary):
    possible_values = {'type': 'string', 'value': f'The highest salary is {highest_salary}.'}
    return possible_values


if __name__ == '__main__':
    dfs = pd.read_csv('data.csv')
    try:
        result = generate_chart(highest_salary)
        plt.imshow(result['value'])
        plt.xticks([])
        plt.yticks([])
        plt.savefig('C:/Users/Anesti/Desktop/New folder (4)/exports/charts/temp_chart.png')
    except Exception as e:
        print(f'Error: {e}')
        ```
2024-08-02 14:49:22 [INFO] Executing Step 6: CodeExecution
2024-08-02 14:49:22 [ERROR] Failed with error: Traceback (most recent call last):
  File "C:\users\anesti\appdata\local\programs\python\python39\lib\site-packages\pandasai\pipelines\chat\code_execution.py", line 85, in execute
    result = self.execute_code(code_to_run, code_context)
  File "C:\users\anesti\appdata\local\programs\python\python39\lib\site-packages\pandasai\pipelines\chat\code_execution.py", line 171, in execute_code
    exec(code, environment)
  File "<string>", line 7, in <module>
  File "C:\users\anesti\appdata\local\programs\python\python39\lib\site-packages\pandas\util\_decorators.py", line 211, in wrapper
    return func(*args, **kwargs)
  File "C:\users\anesti\appdata\local\programs\python\python39\lib\site-packages\pandas\util\_decorators.py", line 331, in wrapper
    return func(*args, **kwargs)
  File "C:\users\anesti\appdata\local\programs\python\python39\lib\site-packages\pandas\io\parsers\readers.py", line 950, in read_csv
    return _read(filepath_or_buffer, kwds)
  File "C:\users\anesti\appdata\local\programs\python\python39\lib\site-packages\pandas\io\parsers\readers.py", line 605, in _read
    parser = TextFileReader(filepath_or_buffer, **kwds)
  File "C:\users\anesti\appdata\local\programs\python\python39\lib\site-packages\pandas\io\parsers\readers.py", line 1442, in __init__
    self._engine = self._make_engine(f, self.engine)
  File "C:\users\anesti\appdata\local\programs\python\python39\lib\site-packages\pandas\io\parsers\readers.py", line 1735, in _make_engine
    self.handles = get_handle(
  File "C:\users\anesti\appdata\local\programs\python\python39\lib\site-packages\pandas\io\common.py", line 856, in get_handle
    handle = open(
FileNotFoundError: [Errno 2] No such file or directory: 'data.csv'

2024-08-02 14:49:22 [WARNING] Failed to execute code retrying with a correction framework [retry number: 1]
2024-08-02 14:49:22 [INFO] Executing Pipeline: ErrorCorrectionPipeline
2024-08-02 14:49:22 [INFO] Executing Step 0: ErrorPromptGeneration
2024-08-02 14:49:22 [INFO] Using prompt: <dataframe>
dfs[0]:4999x10
1,"Eldon Base for stackable storage shelf, platinum",Muhammed MacIntyre,3,-213.25,38.94,35,Nunavut,Storage & Organization,0.8
3766,GBC Standard Therm-A-Bind Covers,Bryan Davis,56646,-1.5,29.17,7.44,Manitoba,Telephones and Communication,0.76
3450,Micro Innovations Media Access Pro Keyboard,Ross DeVincentis,13861,-35.75,376.13,7.23,Ontario,Storage & Organization,0.82
3587,Fellowes Superior 10 Outlet Split Surge Protector,Speros Goranitis,14372,-86.68,8.6,5.53,Quebec,Computer Peripherals,
</dataframe>


The user asked the following question:
### QUERY
 heighest value

You generated this python code:
def generate_chart(highest_salary):
    possible_values = {'type': 'string', 'value': f'The highest salary is {highest_salary}.'}
    return possible_values


if __name__ == '__main__':
    dfs = pd.read_csv('data.csv')
    try:
        result = generate_chart(highest_salary)
        plt.imshow(result['value'])
        plt.xticks([])
        plt.yticks([])
        plt.savefig('C:/Users/Anesti/Desktop/New folder (4)/exports/charts/temp_chart.png')
    except Exception as e:
        print(f'Error: {e}')

It fails with the following error:
Traceback (most recent call last):
  File "C:\users\anesti\appdata\local\programs\python\python39\lib\site-packages\pandasai\pipelines\chat\code_execution.py", line 85, in execute
    result = self.execute_code(code_to_run, code_context)
  File "C:\users\anesti\appdata\local\programs\python\python39\lib\site-packages\pandasai\pipelines\chat\code_execution.py", line 171, in execute_code
    exec(code, environment)
  File "<string>", line 7, in <module>
  File "C:\users\anesti\appdata\local\programs\python\python39\lib\site-packages\pandas\util\_decorators.py", line 211, in wrapper
    return func(*args, **kwargs)
  File "C:\users\anesti\appdata\local\programs\python\python39\lib\site-packages\pandas\util\_decorators.py", line 331, in wrapper
    return func(*args, **kwargs)
  File "C:\users\anesti\appdata\local\programs\python\python39\lib\site-packages\pandas\io\parsers\readers.py", line 950, in read_csv
    return _read(filepath_or_buffer, kwds)
  File "C:\users\anesti\appdata\local\programs\python\python39\lib\site-packages\pandas\io\parsers\readers.py", line 605, in _read
    parser = TextFileReader(filepath_or_buffer, **kwds)
  File "C:\users\anesti\appdata\local\programs\python\python39\lib\site-packages\pandas\io\parsers\readers.py", line 1442, in __init__
    self._engine = self._make_engine(f, self.engine)
  File "C:\users\anesti\appdata\local\programs\python\python39\lib\site-packages\pandas\io\parsers\readers.py", line 1735, in _make_engine
    self.handles = get_handle(
  File "C:\users\anesti\appdata\local\programs\python\python39\lib\site-packages\pandas\io\common.py", line 856, in get_handle
    handle = open(
FileNotFoundError: [Errno 2] No such file or directory: 'data.csv'


Fix the python code above and return the new python code:
2024-08-02 14:49:22 [INFO] Executing Step 1: CodeGenerator
2024-08-02 14:49:22 [INFO] HTTP Request: POST https://api.openai.com/v1/chat/completions "HTTP/1.1 429 Too Many Requests"
2024-08-02 14:49:22 [INFO] Retrying request to /chat/completions in 0.993270 seconds
2024-08-02 14:49:24 [INFO] HTTP Request: POST https://api.openai.com/v1/chat/completions "HTTP/1.1 429 Too Many Requests"
2024-08-02 14:49:24 [INFO] Retrying request to /chat/completions in 1.661855 seconds
2024-08-02 14:49:26 [INFO] HTTP Request: POST https://api.openai.com/v1/chat/completions "HTTP/1.1 429 Too Many Requests"
2024-08-02 14:49:26 [ERROR] Pipeline failed on step 1: Error code: 429 - {'error': {'message': 'You exceeded your current quota, please check your plan and billing details. For more information on this error, read the docs: https://platform.openai.com/docs/guides/error-codes/api-errors.', 'type': 'insufficient_quota', 'param': None, 'code': 'insufficient_quota'}}
2024-08-02 14:49:26 [ERROR] Pipeline failed on step 6: Error code: 429 - {'error': {'message': 'You exceeded your current quota, please check your plan and billing details. For more information on this error, read the docs: https://platform.openai.com/docs/guides/error-codes/api-errors.', 'type': 'insufficient_quota', 'param': None, 'code': 'insufficient_quota'}}
2024-08-02 14:54:02 [INFO] Question: heighest value
2024-08-02 14:54:02 [INFO] Running PandasAI with huggingface-text-generation LLM...
2024-08-02 14:54:02 [INFO] Prompt ID: 1bf48041-5760-4d79-ae5d-9951f692325e
2024-08-02 14:54:02 [INFO] Executing Pipeline: GenerateChatPipeline
2024-08-02 14:54:02 [INFO] Executing Step 0: ValidatePipelineInput
2024-08-02 14:54:02 [INFO] Executing Step 1: CacheLookup
2024-08-02 14:54:03 [INFO] Using cached response
2024-08-02 14:54:03 [INFO] Executing Step 2: PromptGeneration
2024-08-02 14:54:03 [INFO] Executing Step 2: Skipping...
2024-08-02 14:54:03 [INFO] Executing Step 3: CodeGenerator
2024-08-02 14:54:03 [INFO] Executing Step 3: Skipping...
2024-08-02 14:54:03 [INFO] Executing Step 4: CachePopulation
2024-08-02 14:54:03 [INFO] Executing Step 4: Skipping...
2024-08-02 14:54:03 [INFO] Executing Step 5: CodeCleaning
2024-08-02 14:54:03 [INFO] Saving charts to C:\Users\Anesti\Desktop\New folder (4)\exports\charts\temp_chart.png
2024-08-02 14:54:03 [INFO] 
Code running:
```
def generate_chart(highest_salary):
    possible_values = {'type': 'string', 'value': f'The highest salary is {highest_salary}.'}
    return possible_values


if __name__ == '__main__':
    dfs = pd.read_csv('data.csv')
    try:
        result = generate_chart(highest_salary)
        plt.imshow(result['value'])
        plt.xticks([])
        plt.yticks([])
        plt.savefig('C:/Users/Anesti/Desktop/New folder (4)/exports/charts/temp_chart.png')
    except Exception as e:
        print(f'Error: {e}')
        ```
2024-08-02 14:54:03 [INFO] Executing Step 6: CodeExecution
2024-08-02 14:54:03 [ERROR] Failed with error: Traceback (most recent call last):
  File "C:\users\anesti\appdata\local\programs\python\python39\lib\site-packages\pandasai\pipelines\chat\code_execution.py", line 85, in execute
    result = self.execute_code(code_to_run, code_context)
  File "C:\users\anesti\appdata\local\programs\python\python39\lib\site-packages\pandasai\pipelines\chat\code_execution.py", line 171, in execute_code
    exec(code, environment)
  File "<string>", line 7, in <module>
  File "C:\users\anesti\appdata\local\programs\python\python39\lib\site-packages\pandas\util\_decorators.py", line 211, in wrapper
    return func(*args, **kwargs)
  File "C:\users\anesti\appdata\local\programs\python\python39\lib\site-packages\pandas\util\_decorators.py", line 331, in wrapper
    return func(*args, **kwargs)
  File "C:\users\anesti\appdata\local\programs\python\python39\lib\site-packages\pandas\io\parsers\readers.py", line 950, in read_csv
    return _read(filepath_or_buffer, kwds)
  File "C:\users\anesti\appdata\local\programs\python\python39\lib\site-packages\pandas\io\parsers\readers.py", line 605, in _read
    parser = TextFileReader(filepath_or_buffer, **kwds)
  File "C:\users\anesti\appdata\local\programs\python\python39\lib\site-packages\pandas\io\parsers\readers.py", line 1442, in __init__
    self._engine = self._make_engine(f, self.engine)
  File "C:\users\anesti\appdata\local\programs\python\python39\lib\site-packages\pandas\io\parsers\readers.py", line 1735, in _make_engine
    self.handles = get_handle(
  File "C:\users\anesti\appdata\local\programs\python\python39\lib\site-packages\pandas\io\common.py", line 856, in get_handle
    handle = open(
FileNotFoundError: [Errno 2] No such file or directory: 'data.csv'

2024-08-02 14:54:03 [WARNING] Failed to execute code retrying with a correction framework [retry number: 1]
2024-08-02 14:54:03 [INFO] Executing Pipeline: ErrorCorrectionPipeline
2024-08-02 14:54:03 [INFO] Executing Step 0: ErrorPromptGeneration
2024-08-02 14:54:03 [INFO] Using prompt: <dataframe>
dfs[0]:4999x10
1,"Eldon Base for stackable storage shelf, platinum",Muhammed MacIntyre,3,-213.25,38.94,35,Nunavut,Storage & Organization,0.8
4226,V70,Allen Golden,52929,-37.06,135.99,64.2,Prince Edward Island,Appliances,0.45
4219,"Fellowes Smart Surge Ten-Outlet Protector, Platinum",Dan Campbell,9923,216.12,145.98,3.04,Ontario,Chairs & Chairmats,0.49
69,Hewlett-Packard Deskjet 6122 Color Inkjet Printer,Alex Grayson,11269,20.14,54.2,9.45,Manitoba,Paper,
</dataframe>


The user asked the following question:
### QUERY
 heighest value

You generated this python code:
def generate_chart(highest_salary):
    possible_values = {'type': 'string', 'value': f'The highest salary is {highest_salary}.'}
    return possible_values


if __name__ == '__main__':
    dfs = pd.read_csv('data.csv')
    try:
        result = generate_chart(highest_salary)
        plt.imshow(result['value'])
        plt.xticks([])
        plt.yticks([])
        plt.savefig('C:/Users/Anesti/Desktop/New folder (4)/exports/charts/temp_chart.png')
    except Exception as e:
        print(f'Error: {e}')

It fails with the following error:
Traceback (most recent call last):
  File "C:\users\anesti\appdata\local\programs\python\python39\lib\site-packages\pandasai\pipelines\chat\code_execution.py", line 85, in execute
    result = self.execute_code(code_to_run, code_context)
  File "C:\users\anesti\appdata\local\programs\python\python39\lib\site-packages\pandasai\pipelines\chat\code_execution.py", line 171, in execute_code
    exec(code, environment)
  File "<string>", line 7, in <module>
  File "C:\users\anesti\appdata\local\programs\python\python39\lib\site-packages\pandas\util\_decorators.py", line 211, in wrapper
    return func(*args, **kwargs)
  File "C:\users\anesti\appdata\local\programs\python\python39\lib\site-packages\pandas\util\_decorators.py", line 331, in wrapper
    return func(*args, **kwargs)
  File "C:\users\anesti\appdata\local\programs\python\python39\lib\site-packages\pandas\io\parsers\readers.py", line 950, in read_csv
    return _read(filepath_or_buffer, kwds)
  File "C:\users\anesti\appdata\local\programs\python\python39\lib\site-packages\pandas\io\parsers\readers.py", line 605, in _read
    parser = TextFileReader(filepath_or_buffer, **kwds)
  File "C:\users\anesti\appdata\local\programs\python\python39\lib\site-packages\pandas\io\parsers\readers.py", line 1442, in __init__
    self._engine = self._make_engine(f, self.engine)
  File "C:\users\anesti\appdata\local\programs\python\python39\lib\site-packages\pandas\io\parsers\readers.py", line 1735, in _make_engine
    self.handles = get_handle(
  File "C:\users\anesti\appdata\local\programs\python\python39\lib\site-packages\pandas\io\common.py", line 856, in get_handle
    handle = open(
FileNotFoundError: [Errno 2] No such file or directory: 'data.csv'


Fix the python code above and return the new python code:
2024-08-02 14:54:03 [INFO] Executing Step 1: CodeGenerator
2024-08-02 14:54:05 [ERROR] Pipeline failed on step 1: HTTPConnectionPool(host='127.0.0.1', port=8080): Max retries exceeded with url: / (Caused by NewConnectionError('<urllib3.connection.HTTPConnection object at 0x00000207C2B44220>: Failed to establish a new connection: [WinError 10061] No connection could be made because the target machine actively refused it'))
2024-08-02 14:54:05 [ERROR] Pipeline failed on step 6: HTTPConnectionPool(host='127.0.0.1', port=8080): Max retries exceeded with url: / (Caused by NewConnectionError('<urllib3.connection.HTTPConnection object at 0x00000207C2B44220>: Failed to establish a new connection: [WinError 10061] No connection could be made because the target machine actively refused it'))
2024-08-02 14:55:53 [INFO] Question: heighest value
2024-08-02 14:55:53 [INFO] Running PandasAI with huggingface-text-generation LLM...
2024-08-02 14:55:53 [INFO] Prompt ID: 88139d62-a070-4df3-b1d3-f8da1f4edd29
2024-08-02 14:55:53 [INFO] Executing Pipeline: GenerateChatPipeline
2024-08-02 14:55:53 [INFO] Executing Step 0: ValidatePipelineInput
2024-08-02 14:55:53 [INFO] Executing Step 1: CacheLookup
2024-08-02 14:55:54 [INFO] Using cached response
2024-08-02 14:55:54 [INFO] Executing Step 2: PromptGeneration
2024-08-02 14:55:54 [INFO] Executing Step 2: Skipping...
2024-08-02 14:55:54 [INFO] Executing Step 3: CodeGenerator
2024-08-02 14:55:54 [INFO] Executing Step 3: Skipping...
2024-08-02 14:55:54 [INFO] Executing Step 4: CachePopulation
2024-08-02 14:55:54 [INFO] Executing Step 4: Skipping...
2024-08-02 14:55:54 [INFO] Executing Step 5: CodeCleaning
2024-08-02 14:55:54 [INFO] Saving charts to C:\Users\Anesti\Desktop\New folder (4)\exports\charts\temp_chart.png
2024-08-02 14:55:54 [INFO] 
Code running:
```
def generate_chart(highest_salary):
    possible_values = {'type': 'string', 'value': f'The highest salary is {highest_salary}.'}
    return possible_values


if __name__ == '__main__':
    dfs = pd.read_csv('data.csv')
    try:
        result = generate_chart(highest_salary)
        plt.imshow(result['value'])
        plt.xticks([])
        plt.yticks([])
        plt.savefig('C:/Users/Anesti/Desktop/New folder (4)/exports/charts/temp_chart.png')
    except Exception as e:
        print(f'Error: {e}')
        ```
2024-08-02 14:55:54 [INFO] Executing Step 6: CodeExecution
2024-08-02 14:55:54 [ERROR] Failed with error: Traceback (most recent call last):
  File "C:\users\anesti\appdata\local\programs\python\python39\lib\site-packages\pandasai\pipelines\chat\code_execution.py", line 85, in execute
    result = self.execute_code(code_to_run, code_context)
  File "C:\users\anesti\appdata\local\programs\python\python39\lib\site-packages\pandasai\pipelines\chat\code_execution.py", line 171, in execute_code
    exec(code, environment)
  File "<string>", line 7, in <module>
  File "C:\users\anesti\appdata\local\programs\python\python39\lib\site-packages\pandas\util\_decorators.py", line 211, in wrapper
    return func(*args, **kwargs)
  File "C:\users\anesti\appdata\local\programs\python\python39\lib\site-packages\pandas\util\_decorators.py", line 331, in wrapper
    return func(*args, **kwargs)
  File "C:\users\anesti\appdata\local\programs\python\python39\lib\site-packages\pandas\io\parsers\readers.py", line 950, in read_csv
    return _read(filepath_or_buffer, kwds)
  File "C:\users\anesti\appdata\local\programs\python\python39\lib\site-packages\pandas\io\parsers\readers.py", line 605, in _read
    parser = TextFileReader(filepath_or_buffer, **kwds)
  File "C:\users\anesti\appdata\local\programs\python\python39\lib\site-packages\pandas\io\parsers\readers.py", line 1442, in __init__
    self._engine = self._make_engine(f, self.engine)
  File "C:\users\anesti\appdata\local\programs\python\python39\lib\site-packages\pandas\io\parsers\readers.py", line 1735, in _make_engine
    self.handles = get_handle(
  File "C:\users\anesti\appdata\local\programs\python\python39\lib\site-packages\pandas\io\common.py", line 856, in get_handle
    handle = open(
FileNotFoundError: [Errno 2] No such file or directory: 'data.csv'

2024-08-02 14:55:54 [WARNING] Failed to execute code retrying with a correction framework [retry number: 1]
2024-08-02 14:55:54 [INFO] Executing Pipeline: ErrorCorrectionPipeline
2024-08-02 14:55:54 [INFO] Executing Step 0: ErrorPromptGeneration
2024-08-02 14:55:54 [INFO] Using prompt: <dataframe>
dfs[0]:4999x10
1,"Eldon Base for stackable storage shelf, platinum",Muhammed MacIntyre,3,-213.25,38.94,35,Nunavut,Storage & Organization,0.8
3905,"IBM 80 Minute CD-R Spindle, 50/Pack",Shahid Hopkins,37443,-54.08,13.79,9.18,Prince Edward Island,Computer Peripherals,0.81
1052,6162i,Katherine Ducich,96,2819.96,8.75,9.68,New Brunswick,Copiers and Fax,
2545,Xerox 1930,Lena Radford,52162,191.47,10.14,8.29,British Columbia,Storage & Organization,0.47
</dataframe>


The user asked the following question:
### QUERY
 heighest value

You generated this python code:
def generate_chart(highest_salary):
    possible_values = {'type': 'string', 'value': f'The highest salary is {highest_salary}.'}
    return possible_values


if __name__ == '__main__':
    dfs = pd.read_csv('data.csv')
    try:
        result = generate_chart(highest_salary)
        plt.imshow(result['value'])
        plt.xticks([])
        plt.yticks([])
        plt.savefig('C:/Users/Anesti/Desktop/New folder (4)/exports/charts/temp_chart.png')
    except Exception as e:
        print(f'Error: {e}')

It fails with the following error:
Traceback (most recent call last):
  File "C:\users\anesti\appdata\local\programs\python\python39\lib\site-packages\pandasai\pipelines\chat\code_execution.py", line 85, in execute
    result = self.execute_code(code_to_run, code_context)
  File "C:\users\anesti\appdata\local\programs\python\python39\lib\site-packages\pandasai\pipelines\chat\code_execution.py", line 171, in execute_code
    exec(code, environment)
  File "<string>", line 7, in <module>
  File "C:\users\anesti\appdata\local\programs\python\python39\lib\site-packages\pandas\util\_decorators.py", line 211, in wrapper
    return func(*args, **kwargs)
  File "C:\users\anesti\appdata\local\programs\python\python39\lib\site-packages\pandas\util\_decorators.py", line 331, in wrapper
    return func(*args, **kwargs)
  File "C:\users\anesti\appdata\local\programs\python\python39\lib\site-packages\pandas\io\parsers\readers.py", line 950, in read_csv
    return _read(filepath_or_buffer, kwds)
  File "C:\users\anesti\appdata\local\programs\python\python39\lib\site-packages\pandas\io\parsers\readers.py", line 605, in _read
    parser = TextFileReader(filepath_or_buffer, **kwds)
  File "C:\users\anesti\appdata\local\programs\python\python39\lib\site-packages\pandas\io\parsers\readers.py", line 1442, in __init__
    self._engine = self._make_engine(f, self.engine)
  File "C:\users\anesti\appdata\local\programs\python\python39\lib\site-packages\pandas\io\parsers\readers.py", line 1735, in _make_engine
    self.handles = get_handle(
  File "C:\users\anesti\appdata\local\programs\python\python39\lib\site-packages\pandas\io\common.py", line 856, in get_handle
    handle = open(
FileNotFoundError: [Errno 2] No such file or directory: 'data.csv'


Fix the python code above and return the new python code:
2024-08-02 14:55:54 [INFO] Executing Step 1: CodeGenerator
2024-08-02 14:55:54 [ERROR] Pipeline failed on step 1: Extra data: line 1 column 5 (char 4)
2024-08-02 14:55:54 [ERROR] Pipeline failed on step 6: Extra data: line 1 column 5 (char 4)
2024-08-02 14:57:18 [INFO] Question: most characters
2024-08-02 14:57:18 [INFO] Running PandasAI with huggingface-text-generation LLM...
2024-08-02 14:57:18 [INFO] Prompt ID: 9a2420e4-e60e-46a9-bd68-3d57a3ac81b8
2024-08-02 14:57:18 [INFO] Executing Pipeline: GenerateChatPipeline
2024-08-02 14:57:18 [INFO] Executing Step 0: ValidatePipelineInput
2024-08-02 14:57:18 [INFO] Executing Step 1: CacheLookup
2024-08-02 14:57:18 [INFO] Executing Step 2: PromptGeneration
2024-08-02 14:57:18 [INFO] Using prompt: <dataframe>
dfs[0]:19x2
Renato Topalli,renatotopalli6@gmail.com
Anius Kotorri,dq39tp@yahoo.com
Ramiz Maliqati,co4_p3yvcq9h@zoho.com
Vasil Andoni,-gbq2392@icloud.com
</dataframe>




Update this initial code:
```python
# TODO: import the required dependencies
import pandas as pd

# Write code here

# Declare result var: 
type (possible values "string", "number", "dataframe", "plot"). Examples: { "type": "string", "value": f"The highest salary is {highest_salary}." } or { "type": "number", "value": 125 } or { "type": "dataframe", "value": pd.DataFrame({...}) } or { "type": "plot", "value": "temp_chart.png" }

```



### QUERY
 most characters

Variable `dfs: list[pd.DataFrame]` is already declared.

At the end, declare "result" variable as a dictionary of type and value.

If you are asked to plot a chart, use "matplotlib" for charts, save as png.


Generate python code and return full updated code:
2024-08-02 14:57:18 [INFO] Executing Step 3: CodeGenerator
2024-08-02 14:57:18 [ERROR] Pipeline failed on step 3: Extra data: line 1 column 5 (char 4)
2024-08-02 15:45:48 [INFO] Question: most characters
2024-08-02 15:45:49 [INFO] Running PandasAI with bamboo_llm LLM...
2024-08-02 15:45:49 [INFO] Prompt ID: 774b9088-40e5-4379-9e48-1bacee651447
2024-08-02 15:45:49 [INFO] Executing Pipeline: GenerateChatPipeline
2024-08-02 15:45:49 [INFO] Executing Step 0: ValidatePipelineInput
2024-08-02 15:45:49 [INFO] Executing Step 1: CacheLookup
2024-08-02 15:45:49 [INFO] Executing Step 2: PromptGeneration
2024-08-02 15:45:49 [INFO] Executing Step 3: CodeGenerator
2024-08-02 15:45:51 [INFO] Prompt used:
            None
            
2024-08-02 15:45:51 [INFO] Code generated:
            ```
            # TODO: import the required dependencies
import pandas as pd

# Write code here
most_characters = ""
max_length = 0

for df in dfs:
    for column in df.columns:
        for value in df[column]:
            if isinstance(value, str) and len(value) > max_length:
                most_characters = value
                max_length = len(value)

result = {"type": "string", "value": f"The value with the most characters is '{most_characters}' with {max_length} characters."}
            ```
            
2024-08-02 15:45:51 [INFO] Executing Step 4: CachePopulation
2024-08-02 15:45:52 [INFO] Executing Step 5: CodeCleaning
2024-08-02 15:45:52 [INFO] 
Code running:
```
most_characters = ''
max_length = 0
for df in dfs:
    for column in df.columns:
        for value in df[column]:
            if isinstance(value, str) and len(value) > max_length:
                most_characters = value
                max_length = len(value)
result = {'type': 'string', 'value': f"The value with the most characters is '{most_characters}' with {max_length} characters."}
        ```
2024-08-02 15:45:52 [INFO] Executing Step 6: CodeExecution
2024-08-02 15:45:52 [INFO] Executing Step 7: ResultValidation
2024-08-02 15:45:52 [INFO] Answer: {'type': 'string', 'value': "The value with the most characters is 'Avery 05222 Permanent Self-Adhesive File Folder Labels for Typewriters, on Rolls, White, 250/Roll' with 97 characters."}
2024-08-02 15:45:52 [INFO] Executing Step 8: ResultParsing
